Workbook

Sheet 미니게임 61
A1: 코드 | B1: 게임(개발용 이름) | C1: 아이콘 | D1: 카테고리 | E1: 진행 | F1: 조작 | G1: 규칙 | H1: 순위 결정 | I1: 한 판 시간 | J1: 1인 AI 행동 | K1: 1인(AI) | L1: 랜덤 7판 | M1: 비고 | N1: 플레이 위치
A2: G01 | B2: 팽이 난투 | C2: 팽이 | D2: 액션 | E2: 동시 | F2: 원버튼 (탭: 회전 방향 전환 / 꾹: 대시) | G2: 원형 경기장에서 서로 부딪혀 밖으로 밀어낸다 | H2: 탈락 역순 | I2: 40초 | J2: 가장 가까운 상대 추적, 가장자리에선 회피 | K2: 가능 | L2: O | N2: 일반 모드
A3: G02 | B3: 줄다리기 리듬 | C3: 밧줄 | D3: 타이밍 | E3: 동시 | F3: 원버튼 (박자 탭) | G3: 박자에 맞춰 탭하면 줄이 내 쪽으로 당겨지고 빗나가면 끌려간다. 3~4인은 중앙 매듭을 각 방향으로 당김 | H3: 매듭에 가까운 순 | I3: 30초 | J3: 박자 적중률(쉬움 60% / 보통 75% / 어려움 90%) | K3: 가능 | L3: O | N3: 일반 모드
A4: G03 | B4: 폭탄 피하기 | C4: 폭탄 | D4: 액션 | E4: 동시 | F4: 2버튼 (좌/우) | G4: 떨어지는 폭탄을 피해 버틴다. 조작 반전·감속 아이템 등장 | H4: 생존 시간 | I4: 60초 | J4: 낙하 지점 예측 회피, 반응 지연으로 난이도 조절 | K4: 가능 | L4: O | N4: 일반 모드
A5: G04 | B5: 땅따먹기 페인트 | C5: 페인트 롤러 | D5: 액션 | E5: 동시 | F5: 조이스틱 | G5: 지나간 바닥이 내 색으로 칠해지고 상대 색도 덮어쓸 수 있다 | H5: 칠한 면적 | I5: 60초 | J5: 가까운 빈칸·상대 색 쪽으로 이동 | K5: 가능 | L5: O | N5: 일반 모드
A6: G05 | B6: 거짓말쟁이 그림 릴레이 | C6: 물음표 붓 | D6: 파티 | E6: 턴 | F6: 손가락 그리기 + 투표 탭 | G6: 1명만 제시어를 모른 채 한 획씩 그린 뒤 라이어를 투표한다 | H6: 라이어 적발 시 나머지 승 / 실패 시 라이어 승 | I6: 3분 | J6: - | K6: 미지원 | L6: X | M6: 사람 3명 이상. 제시어는 그림으로 표시 | N6: 파티 모드 전용
A7: G06 | B7: 폭탄 돌리기 퀴즈 | C7: 도화선 폭탄 | D7: 턴제 | E7: 턴 | F7: 탭 (보기 선택) | G7: 상식·넌센스 문제를 맞히면 폰을 다음 사람에게 넘긴다. 타이머는 숨겨져 있음 | H7: 터질 때 든 사람 탈락, 마지막 생존자 1위 | I7: 2분 | J7: 정답률·답하는 시간 난이도별 | K7: 가능 | L7: O | M7: 학습 문제 없이 상식·넌센스만 | N7: 일반 모드
A8: G07 | B8: 비밀 경매 | C8: 경매 망치 | D8: 심리 | E8: 동시(가림) | F8: 슬라이더로 입찰 후 확정 | G8: 매 라운드 물건이 나오면 모두 몰래 입찰하고 동시 공개, 최고가 낙찰. 코인은 한정 | H8: 얻은 물건 가치 합 | I8: 5라운드 · 2분 | J8: 물건 가치 기준 랜덤 범위로 입찰 | K8: 가능 | L8: O | M8: 입찰할 때 손으로 가리기 | N8: 일반 모드
A9: G08 | B9: 두 명이 한 우주선 | C9: 우주선 | D9: 협동 | E9: 동시 | F9: 조종: 2버튼 / 사격: 원버튼 | G9: 2인 1팀으로 운석·적 격파. 4인은 2:2 대결, 3인은 1:2(1인 팀 자동 사격 보조), 2인은 협동 목표 점수 | H9: 팀 점수 (2인은 목표 달성 여부) | I9: 60초 | J9: 1인: AI가 사격 담당 | K9: 가능 | L9: O | M9: 랜덤 7판에서는 개인 격파 수로 순위 | N9: 일반 모드
A10: G09 | B10: 눈치 탭 | C10: 신호등 | D10: 순발력 | E10: 동시 | F10: 원버튼 | G10: 초록불에 먼저 탭 +1, 빨간불에 탭 -1, 노란불 페이크 | H10: 점수 | I10: 5라운드 · 30초 | J10: 반응 0.25~0.45초, 낮은 확률로 페이크에 속음 | K10: 가능 | L10: O | N10: 일반 모드
A11: G10 | B11: 같은 그림 찾기 | C11: 돋보기 | D11: 두뇌 | E11: 동시 | F11: 탭 | G11: 중앙 카드와 같은 그림을 내 구역 카드 중에서 먼저 찾아 탭 | H11: 맞힌 수 | I11: 45초 | J11: 탐색 시간 난이도별 | K11: 가능 | L11: O | N11: 일반 모드
A12: G11 | B12: 두더지 쟁탈전 | C12: 두더지 | D12: 순발력 | E12: 동시 | F12: 탭 | G12: 중앙 구멍에서 나온 두더지를 먼저 때린다. 황금 3점, 폭탄 -2점 | H12: 점수 | I12: 40초 | J12: 반응 속도, 폭탄 회피율 | K12: 가능 | L12: O | N12: 일반 모드
A13: G12 | B13: 에어하키 난전 | C13: 하키 퍽 | D13: 액션 | E13: 동시 | F13: 드래그 (말렛) | G13: 각자 자기 골대를 지키고 실점하면 체력 -1 | H13: 탈락 역순 / 남은 체력 | I13: 60초 | J13: 퍽 경로 예측 방어 | K13: 가능 | L13: O | N13: 일반 모드
A14: G13 | B14: 스모 밀어내기 | C14: 씨름 링 | D14: 액션 | E14: 동시 | F14: 원버튼 (연타로 힘 모으고 떼면 돌진) | G14: 링 밖으로 상대를 밀어낸다 | H14: 탈락 역순 | I14: 40초 | J14: 힘 모으는 시간 난이도별 | K14: 가능 | L14: O | N14: 일반 모드
A15: G14 | B15: 블록 탑 쌓기 | C15: 블록 | D15: 타이밍 | E15: 동시 | F15: 원버튼 (떨어뜨리기) | G15: 흔들리는 블록을 자기 탑에 떨어뜨려 쌓고 무너지면 탈락 | H15: 높이 / 생존 | I15: 60초 | J15: 중앙 정렬 오차 난이도별 | K15: 가능 | L15: O | N15: 일반 모드
A16: G15 | B16: 숫자 폭탄 경매 | C16: 숫자판 | D16: 심리 | E16: 동시(가림) | F16: 숫자 1~9 선택 | G16: 가장 낮은 '고유' 숫자를 낸 사람이 득점 | H16: 득점 | I16: 5라운드 | J16: 확률 분포로 숫자 선택 | K16: 가능 | L16: O | M16: 선택할 때 손으로 가리기 | N16: 일반 모드
A17: G16 | B17: 숫자 빨리 세기 | C17: 점 묶음 | D17: 두뇌 | E17: 동시 | F17: 탭 (보기 3개) | G17: 순간적으로 뜬 점·물건의 총 개수를 먼저 맞힌다 | H17: 정답 수 | I17: 45초 | J17: 정답률·속도 난이도별 | K17: 가능 | L17: O | M17: 암산 레이스를 학습 요소 없이 바꾼 것 | N17: 일반 모드
A18: G17 | B18: 한 줄 이어 그리기 | C18: 연필 선 | D18: 파티 | E18: 턴 | F18: 손가락 그리기 | G18: 1인당 선 하나씩 그려 제시어 그림을 완성하고 마지막 사람이 맞힌다 | H18: 정답 시 전원 득점 | I18: 2분 | J18: - | K18: 미지원 | L18: X | N18: 파티 모드 전용
A19: G18 | B19: 기억력 릴레이 | C19: 4색 전구 | D19: 두뇌 | E19: 턴 | F19: 4색 버튼 | G19: 앞사람이 누른 순서에 하나씩 추가하며 따라 누르고 틀리면 탈락 | H19: 생존 순 | I19: 약 2분 | J19: 기억 한계 6 / 10 / 15개 | K19: 가능 | L19: O | N19: 일반 모드
A20: G19 | B20: 칼 뽑기 결투 | C20: 교차한 칼 | D20: 순발력 | E20: 동시 | F20: 원버튼 | G20: 신호가 뜨는 순간 먼저 탭. 신호 전에 누르면 자멸 | H20: 반응 속도 | I20: 5라운드 | J20: 반응 시간 난이도별 | K20: 가능 | L20: O | M20: 동점 서든데스용으로도 사용 | N20: 일반 모드
A21: G20 | B21: 가위바위보 스피드전 | C21: 손 | D21: 순발력 | E21: 동시 | F21: 3버튼 (가위/바위/보) | G21: 중앙에 뜬 손을 이기는 버튼을 먼저 누른다 | H21: 점수 | I21: 30초 | J21: 반응 + 오답률 | K21: 가능 | L21: O | N21: 일반 모드
A22: G21 | B22: 색깔 함정 | C22: 색 글자 | D22: 순발력 | E22: 동시 | F22: 4색 버튼 | G22: 색 이름 글자가 다른 색으로 뜨면 '글자의 색'을 누른다 | H22: 점수 | I22: 30초 | J22: 오답률 난이도별 | K22: 가능 | L22: O | N22: 일반 모드
A23: G22 | B23: 별 받기 | C23: 별 | D23: 액션 | E23: 동시 | F23: 2버튼 (좌/우) | G23: 바구니를 움직여 떨어지는 별을 받는다. 남의 쪽 별도 가로챌 수 있음 | H23: 받은 개수 | I23: 45초 | J23: 가장 가까운 별 추적 | K23: 가능 | L23: O | N23: 일반 모드
A24: G23 | B24: 풍선 터뜨리기 | C24: 풍선 | D24: 순발력 | E24: 동시 | F24: 탭 | G24: 자기 색 풍선만 터뜨린다. 남의 색을 터뜨리면 그 사람 +1 | H24: 점수 | I24: 40초 | J24: 자기 색 인식 속도, 오터치 확률 | K24: 가능 | L24: O | N24: 일반 모드
A25: G24 | B25: 구슬치기 | C25: 구슬 | D25: 액션 | E25: 턴 | F25: 당겨서 튕기기 | G25: 상대 구슬을 판 밖으로 쳐낸다 | H25: 남은 구슬 수 | I25: 2분 | J25: 조준 오차 난이도별 | K25: 가능 | L25: O | N25: 일반 모드
A26: G25 | B26: 빙판 컬링 | C26: 컬링 스톤 | D26: 액션 | E26: 턴 | F26: 당겨서 밀기 | G26: 돌을 과녁 중심 가까이 세우고 상대 돌은 쳐낸다 | H26: 중심 거리순 | I26: 3엔드 · 2분 | J26: 힘·방향 오차 난이도별 | K26: 가능 | L26: O | N26: 일반 모드
A27: G26 | B27: 뱀 꼬리 잡기 | C27: 뱀 | D27: 액션 | E27: 동시 | F27: 2버튼 (좌회전/우회전) | G27: 지나간 자리에 벽이 생기고 부딪히면 탈락 | H27: 탈락 역순 | I27: 60초 | J27: 빈 공간이 넓은 쪽으로 회전 | K27: 가능 | L27: O | N27: 일반 모드
A28: G27 | B28: 탱크 대전 | C28: 탱크 | D28: 액션 | E28: 동시 | F28: 2버튼 (회전/발사) | G28: 총알이 벽에 튕기며 3번 맞으면 탈락 | H28: 탈락 역순 | I28: 60초 | J28: 조준·반사 각 계산 정확도 | K28: 가능 | L28: O | N28: 일반 모드
A29: G28 | B29: 줄넘기 생존 | C29: 줄넘기 | D29: 타이밍 | E29: 동시 | F29: 원버튼 (점프) | G29: 중앙에서 도는 줄을 타이밍 맞춰 넘는다. 점점 빨라짐 | H29: 생존 | I29: 60초 | J29: 점프 타이밍 오차 | K29: 가능 | L29: O | N29: 일반 모드
A30: G29 | B30: 카트 레이스 | C30: 체크 깃발 | D30: 액션 | E30: 동시 | F30: 2버튼 (좌/우 핸들) | G30: 위에서 보는 트랙을 3바퀴 먼저 돈다 | H30: 도착순 | I30: 90초 | J30: 정해진 주행 라인 추종 | K30: 가능 | L30: O | N30: 일반 모드
A31: G30 | B31: 회전판 점프 | C31: 회전 레이저 | D31: 타이밍 | E31: 동시 | F31: 원버튼 (점프) | G31: 중앙에서 회전하는 레이저를 점프로 넘는다 | H31: 생존 | I31: 60초 | J31: 점프 타이밍 오차 | K31: 가능 | L31: O | N31: 일반 모드
A32: G31 | B32: 치킨 게임 | C32: 게이지 폭탄 | D32: 심리 | E32: 동시 | F32: 꾹 누르고 떼기 | G32: 누르는 동안 점수가 오르고 떼면 그 점수 획득. 랜덤 폭발 시 누르고 있던 사람은 0점 | H32: 점수 합 | I32: 5라운드 | J32: 목표 점수 랜덤 + 상대 눈치 | K32: 가능 | L32: O | N32: 일반 모드
... A39: G38 | B39: 개수 세기 | C39: 동물 무리 | D39: 두뇌 | E39: 동시 | F39: 탭 (보기) | G39: 동물 무리가 지나간 뒤 특정 동물이 몇 마리였는지 먼저 맞힌다 | H39: 정답 수 | I39: 5라운드 | J39: 정답률·속도 | K39: 가능 | L39: O | N39: 일반 모드
A40: G39 | B40: 흔들지 마 | C40: 쟁반 구슬 | D40: 폰기능 | E40: 턴 | F40: 기울기 | G40: 폰을 쟁반처럼 들고 구슬을 안 떨어뜨리며 버틴 뒤 다음 사람에게 넘긴다 | H40: 버틴 시간 | I40: 2분 | J40: 1인: AI 기록과 대결 | K40: 가능 | L40: O | M40: iOS 모션 권한 필요 | N40: 일반 모드
A41: G40 | B41: 소리 크기 대결 | C41: 메가폰 | D41: 폰기능 | E41: 턴 | F41: 마이크 | G41: 소리를 질러 게이지를 채운다 | H41: 최대 게이지 | I41: 1분 | J41: 1인: AI 기록과 대결 | K41: 가능 | L41: O | M41: 마이크 권한 필요 | N41: 일반 모드
A42: G41 | B42: 순서 맞추기 퀴즈 | C42: 정렬 화살표 | D42: 두뇌 | E42: 동시 | F42: 드래그 | G42: 4개 항목을 크기·무게 등 순서대로 먼저 배열(상식·넌센스) | H42: 정답 + 속도 | I42: 5라운드 | J42: 정답률·속도 | K42: 가능 | L42: O | M42: 학습 문제 없이 상식만 | N42: 일반 모드
A43: G42 | B43: 진실 탐지기 | C43: 탐지기 그래프 | D43: 파티 | E43: 턴 | F43: 손바닥 올리기 | G43: 질문에 답하는 동안 랜덤으로 '거짓!' 판정이 나온다(웃자고 하는 게임) | H43: 점수 없음 | I43: 2분 | J43: - | K43: 미지원 | L43: X | M43: 순위가 없어 랜덤 7판 제외 | N43: 파티 모드 전용
A44: G43 | B44: 폭탄 해체반 | C44: 전선 가위 | D44: 심리 | E44: 턴 | F44: 탭 | G44: 돌아가며 전선을 하나씩 끊고 꽝 선을 끊으면 탈락 | H44: 생존 순 | I44: 1분 | J44: 랜덤 선택 | K44: 가능 | L44: O | N44: 일반 모드
A45: G44 | B45: 화면 회전 혼돈 | C45: 회전 화살표 | D45: 액션 | E45: 동시 | F45: 원버튼 | G45: 코인 모으기 중 화면이 90도씩 돌아 내 버튼 위치가 바뀐다 | H45: 코인 수 | I45: 45초 | J45: 회전 후 적응 지연 | K45: 가능 | L45: O | N45: 일반 모드
A46: G45 | B46: 어둠 속 손전등 | C46: 손전등 | D46: 두뇌 | E46: 동시 | F46: 드래그 (손가락 위치가 빛) | G46: 깜깜한 화면에서 숨은 아이템을 먼저 찾는다 | H46: 찾은 개수 | I46: 45초 | J46: 탐색 경로 랜덤 + 속도 | K46: 가능 | L46: O | N46: 일반 모드
...

Sheet 공통 규칙
A1: 항목 | B1: 내용
A2: 인원 | B2: 1인은 AI 상대(또는 AI 팀원), 2~4인은 사람끼리만. 2인은 위아래 마주 보기, 3~4인은 네 모서리 고정
A3: 진영 | B3: 빨강(좌상) · 파랑(우상) · 노랑(좌하) · 초록(우하). 모든 화면에서 위치·색 고정
A4: 캐릭터 | B4: 꾹이·레버·땡그랑·캡슐. 크기·판정·능력치 완전히 동일, 차이는 겉모습·애니메이션·소리만
A5: 게임 표시 | B5: 게임 이름·설명 없이 아이콘만. 시작은 아이콘 → 3, 2, 1 → 바로 시작
A6: 익히기 | B6: 설명·시연 없음. 누를 수 있는 순간 버튼이 빛남, 탭하면 즉시 반응, 첫 몇 초는 실패해도 손해 적게
A7: 플레이 방법 | B7: 게임별 방법은 별도 파일로 정리, 게임 안에선 일시정지 메뉴의 '?'로 연결
A8: 파티 게임 분리 | B8: 카테고리가 '파티'인 7종은 파티 모드에서만 플레이. 랜덤 7판·토너먼트·보드·아케이드에 섞이지 않음
A9: 순위점 (랜덤 7판) | B9: 판마다 1위 = 참가 인원 수만큼, 한 순위 내려갈 때마다 1점씩 감소. 4인 4/3/2/1, 3인 3/2/1, 2인 2/1. 공동 순위는 같은 점수
A10: 1인 순위점 | B10: 1인은 AI 포함 4명 기준으로 4/3/2/1 계산, 사람 순위만 결과에 강조
A11: 동점 처리 | B11: ① 1위 횟수 많은 사람 ② 7번째 판 순위 ③ 칼 뽑기 결투(G19) 서든데스 1판
A12: 랜덤 뽑기 규칙 | B12: 현재 인원으로 가능한 게임만 · 같은 카테고리 3판 연속 금지 · 직전 세트에 나온 게임은 가중치 낮춤
... A17: 캐릭터 등장 범위 | B17: 캐릭터(꾹이·레버·땡그랑·캡슐)는 로비·참가·결과·보드 화면에만 등장. 미니게임 안에서는 게임에 맞는 말(탱크, 카트, 바구니 등)을 진영색으로 쓰고, 말 위에 작은 진영 표식을 띄움

Sheet 모드
A1: 모드 | B1: 인원 | C1: 진행 방식 | D1: 승리 조건 | E1: 예상 시간 | F1: 비고
A2: 랜덤 7판 총점 | B2: 1~4인 | C2: '랜덤 7판' 열이 O인 게임 중 7개를 중복 없이 랜덤으로 뽑아 연속 진행. 시작 전에 슬롯머신처럼 아이콘 7개가 차례로 공개됨 | D2: 7판 순위점 합계 1위가 우승 | E2: 약 7~15분 | F2: 순위점·동점 규칙은 '공통 규칙' 시트
A3: 아케이드 | B3: 1~4인 | C3: 오락기(카테고리)를 골라 아이콘 그리드에서 미니게임 1개 선택 후 바로 시작 | D3: 판마다 순위 발표 | E3: 판당 30초~3분 | F3: 첫 화면 메인
A4: 토너먼트 | B4: 2~4인 | C4: 미니게임 랜덤 연속 진행, 판마다 1위가 1승 | D4: 목표 승수(3/5/7승) 먼저 달성 | E4: 10~20분
A5: 보드 모드 | B5: 1~4인 | C5: 보드판을 주사위로 이동, 칸 색에 맞는 카테고리 미니게임 발생, 라운드 끝마다 전원 미니게임, 마지막은 협동 보스전 | D5: 별 개수 (동점 시 코인) | E5: 30~60분 | F5: 10/15/20라운드 선택
A6: 솔로 도전 | B6: 1인 | C6: AI 상대로 62개 중 1인 가능한 게임을 하나씩 클리어 | D6: 전부 클리어 | E6: 자유 | F6: 클리어 기록 저장
A7: 파티 모드 | B7: 2~4인 (일부 3인 이상) | C7: 파티 게임 7종만 따로 모아 플레이. 일반 모드(아케이드·랜덤 7판·토너먼트·보드)에는 나오지 않음. 점수 없이 즐기거나 판별 승패만 표시 | D7: 게임별 (총점 없음) | E7: 자유 | F7: 1인 불가. 인원이 부족한 게임은 회색 처리
A8: 연습 | B8: 1~4인 | C8: 원하는 미니게임 자유 플레이, 점수 기록 없음 | D8: - | E8: 자유

Sheet 요약
A1: 카테고리 | B1: 게임 수 | C1: 랜덤 7판 포함
A2: 순발력 | B2: =COUNTIF('미니게임 61'!$D$2:$D$62,A2) -> 7 | C2: =COUNTIFS('미니게임 61'!$D$2:$D$62,A2,'미니게임 61'!$L$2:$L$62,"O") -> 7
A3: 액션 | B3: =COUNTIF('미니게임 61'!$D$2:$D$62,A3) -> 15 | C3: =COUNTIFS('미니게임 61'!$D$2:$D$62,A3,'미니게임 61'!$L$2:$L$62,"O") -> 15
A4: 타이밍 | B4: =COUNTIF('미니게임 61'!$D$2:$D$62,A4) -> 8 | C4: =COUNTIFS('미니게임 61'!$D$2:$D$62,A4,'미니게임 61'!$L$2:$L$62,"O") -> 8
A5: 두뇌 | B5: =COUNTIF('미니게임 61'!$D$2:$D$62,A5) -> 10 | C5: =COUNTIFS('미니게임 61'!$D$2:$D$62,A5,'미니게임 61'!$L$2:$L$62,"O") -> 10
A6: 심리 | B6: =COUNTIF('미니게임 61'!$D$2:$D$62,A6) -> 7 | C6: =COUNTIFS('미니게임 61'!$D$2:$D$62,A6,'미니게임 61'!$L$2:$L$62,"O") -> 7
A7: 협동 | B7: =COUNTIF('미니게임 61'!$D$2:$D$62,A7) -> 2 | C7: =COUNTIFS('미니게임 61'!$D$2:$D$62,A7,'미니게임 61'!$L$2:$L$62,"O") -> 2
A8: 폰기능 | B8: =COUNTIF('미니게임 61'!$D$2:$D$62,A8) -> 3 | C8: =COUNTIFS('미니게임 61'!$D$2:$D$62,A8,'미니게임 61'!$L$2:$L$62,"O") -> 3
A9: 턴제 | B9: =COUNTIF('미니게임 61'!$D$2:$D$62,A9) -> 2 | C9: =COUNTIFS('미니게임 61'!$D$2:$D$62,A9,'미니게임 61'!$L$2:$L$62,"O") -> 2
A10: 파티 | B10: =COUNTIF('미니게임 61'!$D$2:$D$62,A10) -> 7 | C10: =COUNTIFS('미니게임 61'!$D$2:$D$62,A10,'미니게임 61'!$L$2:$L$62,"O") -> 0
A11: 합계 | B11: =SUM(B2:B10) -> 61 | C11: =SUM(C2:C10) -> 54
A13: 진행 방식 | B13: 게임 수
A14: 동시 | B14: =COUNTIF('미니게임 61'!$E$2:$E$62,A14) -> 42
A15: 동시(가림) | B15: =COUNTIF('미니게임 61'!$E$2:$E$62,A15) -> 3
A16: 턴 | B16: =COUNTIF('미니게임 61'!$E$2:$E$62,A16) -> 16
A18: 1인(AI) 미지원 | B18: =COUNTIF('미니게임 61'!$K$2:$K$62,"미지원") -> 6
